Workbook
Name UPDATE: 'Data Sheet'!$E$1

Sheet Profit & Loss
A1: ='Data Sheet'!B1 -> ASIAN PAINTS LTD | H1: =UPDATE | M1: SCREENER.IN
A3: Narration | B3: ='Data Sheet'!B16 -> 42460 | C3: ='Data Sheet'!C16 -> 42825 | D3: ='Data Sheet'!D16 -> 43190 | E3: ='Data Sheet'!E16 -> 43555 | F3: ='Data Sheet'!F16 -> 43921 | G3: ='Data Sheet'!G16 -> 44286 | H3: ='Data Sheet'!H16 -> 44651 | I3: ='Data Sheet'!I16 -> 45016 | ... K3: ='Data Sheet'!K16 -> 45747 | L3: Trailing | M3: Best Case | N3: Worst Case
A4: Sales | B4: ='Data Sheet'!B17 -> 14271.49 | C4: ='Data Sheet'!C17 -> 15061.99 | D4: ='Data Sheet'!D17 -> 16824.55 | E4: ='Data Sheet'!E17 -> 19240.13 | F4: ='Data Sheet'!F17 -> 20211.25 | G4: ='Data Sheet'!G17 -> 21712.79 | H4: ='Data Sheet'!H17 -> 29101.28 | I4: ='Data Sheet'!I17 -> 34488.59 | ... K4: ='Data Sheet'!K17 -> 33905.62 | L4: =SUM(Quarters!H4:K4) -> 34695.75 | M4: =$K4+M23*K4 -> 35677.265 | N4: =$K4+N23*L4 -> 34714.163
A5: Expenses | B5: =SUM('Data Sheet'!B18,'Data Sheet'!B20:B24, -1*'Data Sheet'!B19) -> 11546.45 | C5: =SUM('Data Sheet'!C18,'Data Sheet'!C20:C24, -1*'Data Sheet'!C19) -> 12068.23 | D5: =SUM('Data Sheet'!D18,'Data Sheet'!D20:D24, -1*'Data Sheet'!D19) -> 13620.54 | E5: =SUM('Data Sheet'!E18,'Data Sheet'!E20:E24, -1*'Data Sheet'!E19) -> 15475.19 | F5: =SUM('Data Sheet'!F18,'Data Sheet'!F20:F24, -1*'Data Sheet'!F19) -> 16043.86 | G5: =SUM('Data Sheet'!G18,'Data Sheet'!G20:G24, -1*'Data Sheet'!G19) -> 16857.19 | H5: =SUM('Data Sheet'!H18,'Data Sheet'!H20:H24, -1*'Data Sheet'!H19) -> 24297.67 | I5: =SUM('Data Sheet'!I18,'Data Sheet'!I20:I24, -1*'Data Sheet'!I19) -> 28228.75 | ... K5: =SUM('Data Sheet'!K18,'Data Sheet'!K20:K24, -1*'Data Sheet'!K19) -> 27899.41 | L5: =SUM(Quarters!H5:K5) -> 28350.24 | M5: =M4-M6 -> 28860.077 | N5: =N4-N6 -> 28365.285
A6: Operating Profit | B6: =B4-B5 -> 2725.04 | C6: =C4-C5 -> 2993.76 | D6: =D4-D5 -> 3204.01 | E6: =E4-E5 -> 3764.94 | F6: =F4-F5 -> 4167.39 | G6: =G4-G5 -> 4855.6 | H6: =H4-H5 -> 4803.61 | I6: =I4-I5 -> 6259.84 | ... K6: =K4-K5 -> 6006.21 | L6: =SUM(Quarters!H6:K6) -> 6345.51 | M6: =M4*M24 -> 6817.1883 | N6: =N4*N24 -> 6348.8776
A7: Other Income | B7: ='Data Sheet'!B25 -> 213.39 | C7: ='Data Sheet'!C25 -> 337.9 | D7: ='Data Sheet'!D25 -> 336.41 | E7: ='Data Sheet'!E25 -> 273.77 | F7: ='Data Sheet'!F25 -> 350.1 | G7: ='Data Sheet'!G25 -> 331.65 | H7: ='Data Sheet'!H25 -> 295.88 | I7: ='Data Sheet'!I25 -> 431.46 | ... K7: ='Data Sheet'!K25 -> 350.22 | L7: =SUM(Quarters!H7:K7) -> 475.13 | M7: 0 | N7: 0
A8: Depreciation | B8: ='Data Sheet'!B26 -> 275.58 | C8: ='Data Sheet'!C26 -> 334.79 | D8: ='Data Sheet'!D26 -> 360.47 | E8: ='Data Sheet'!E26 -> 622.14 | F8: ='Data Sheet'!F26 -> 780.5 | G8: ='Data Sheet'!G26 -> 791.27 | H8: ='Data Sheet'!H26 -> 816.36 | I8: ='Data Sheet'!I26 -> 858.02 | ... K8: ='Data Sheet'!K26 -> 1026.34 | L8: =SUM(Quarters!H8:K8) -> 1219.97 | M8: =+$L8 -> 1219.97 | N8: =+$L8 -> 1219.97
A9: Interest | B9: ='Data Sheet'!B27 -> 49 | C9: ='Data Sheet'!C27 -> 37.33 | D9: ='Data Sheet'!D27 -> 41.47 | E9: ='Data Sheet'!E27 -> 110.47 | F9: ='Data Sheet'!F27 -> 107.95 | G9: ='Data Sheet'!G27 -> 91.63 | H9: ='Data Sheet'!H27 -> 95.41 | I9: ='Data Sheet'!I27 -> 144.45 | ... K9: ='Data Sheet'!K27 -> 227.02 | L9: =SUM(Quarters!H9:K9) -> 189.1 | M9: =+$L9 -> 189.1 | N9: =+$L9 -> 189.1
A10: Profit before tax | B10: ='Data Sheet'!B28 -> 2613.85 | C10: ='Data Sheet'!C28 -> 2959.54 | D10: ='Data Sheet'!D28 -> 3138.48 | E10: ='Data Sheet'!E28 -> 3306.1 | F10: ='Data Sheet'!F28 -> 3629.04 | G10: ='Data Sheet'!G28 -> 4304.35 | H10: ='Data Sheet'!H28 -> 4187.72 | I10: ='Data Sheet'!I28 -> 5688.83 | ... K10: ='Data Sheet'!K28 -> 5103.07 | L10: =SUM(Quarters!H10:K10) -> 5411.57 | M10: =M6+M7-SUM(M8:M9) -> 5408.1183 | N10: =N6+N7-SUM(N8:N9) -> 4939.8076
A11: Tax | B11: ='Data Sheet'!B29 -> 844.49 | C11: ='Data Sheet'!C29 -> 943.29 | D11: ='Data Sheet'!D29 -> 1040.96 | E11: ='Data Sheet'!E29 -> 1098.06 | F11: ='Data Sheet'!F29 -> 854.85 | G11: ='Data Sheet'!G29 -> 1097.6 | H11: ='Data Sheet'!H29 -> 1102.91 | I11: ='Data Sheet'!I29 -> 1493.5 | ... K11: ='Data Sheet'!K29 -> 1393.36 | L11: =SUM(Quarters!H11:K11) -> 1501.54 | M11: =IF($L10>0,$L11/$L10,0) -> 0.27746846 | N11: =IF($L10>0,$L11/$L10,0) -> 0.27746846
A12: Net profit | B12: ='Data Sheet'!B30 -> 1745.16 | C12: ='Data Sheet'!C30 -> 1939.43 | D12: ='Data Sheet'!D30 -> 2038.93 | E12: ='Data Sheet'!E30 -> 2155.92 | F12: ='Data Sheet'!F30 -> 2705.17 | G12: ='Data Sheet'!G30 -> 3139.29 | H12: ='Data Sheet'!H30 -> 3030.57 | I12: ='Data Sheet'!I30 -> 4106.45 | ... K12: ='Data Sheet'!K30 -> 3667.23 | L12: =SUM(Quarters!H12:K12) -> 3845.36 | M12: =M10-M11*M10 -> 3907.536 | N12: =N10-N11*N10 -> 3569.1668
A13: EPS | B13: =IF('Data Sheet'!B93>0,B12/'Data Sheet'!B93,0) -> 18.193912 | C13: =IF('Data Sheet'!C93>0,C12/'Data Sheet'!C93,0) -> 20.219245 | D13: =IF('Data Sheet'!D93>0,D12/'Data Sheet'!D93,0) -> 21.256568 | E13: =IF('Data Sheet'!E93>0,E12/'Data Sheet'!E93,0) -> 22.47623 | F13: =IF('Data Sheet'!F93>0,F12/'Data Sheet'!F93,0) -> 28.202356 | G13: =IF('Data Sheet'!G93>0,G12/'Data Sheet'!G93,0) -> 32.728211 | H13: =IF('Data Sheet'!H93>0,H12/'Data Sheet'!H93,0) -> 31.594766 | I13: =IF('Data Sheet'!I93>0,I12/'Data Sheet'!I93,0) -> 42.811197 | ... K13: =IF('Data Sheet'!K93>0,K12/'Data Sheet'!K93,0) -> 38.232173 | L13: =IF('Data Sheet'!$B6>0,'Profit & Loss'!L12/'Data Sheet'!$B6,0) -> 40.090176 | M13: =IF('Data Sheet'!$B6>0,'Profit & Loss'!M12/'Data Sheet'!$B6,0) -> 40.738398 | N13: =IF('Data Sheet'!$B6>0,'Profit & Loss'!N12/'Data Sheet'!$B6,0) -> 37.210697
A14: Price to earning | B14: =IF(B15>0,B15/B13,"") -> 47.730253 | C14: =IF(C15>0,C15/C13,"") -> 53.092981 | D14: =IF(D15>0,D15/D13,"") -> 52.708415 | E14: =IF(E15>0,E15/E13,"") -> 66.412383 | F14: =IF(F15>0,F15/F13,"") -> 59.090808 | G14: =IF(G15>0,G15/G13,"") -> 77.529444 | H14: =IF(H15>0,H15/H13,"") -> 97.482917 | I14: =IF(I15>0,I15/I13,"") -> 64.507657 | ... K14: =IF(K15>0,K15/K13,"") -> 61.221998 | L14: =IF(L13>0,L15/L13,0) -> 57.547764 | M14: =M25 -> 58.321587 | N14: =N25 -> 57.547764
A15: Price | B15: ='Data Sheet'!B90 -> 868.4 | C15: ='Data Sheet'!C90 -> 1073.5 | D15: ='Data Sheet'!D90 -> 1120.4 | E15: ='Data Sheet'!E90 -> 1492.7 | F15: ='Data Sheet'!F90 -> 1666.5 | G15: ='Data Sheet'!G90 -> 2537.4 | H15: ='Data Sheet'!H90 -> 3079.95 | I15: ='Data Sheet'!I90 -> 2761.65 | ... K15: ='Data Sheet'!K90 -> 2340.65 | L15: ='Data Sheet'!B8 -> 2307.1 | M15: =M13*M14 -> 2375.928 | N15: =N13*N14 -> 2141.3924
A17: RATIOS:
A18: Dividend Payout | B18: =IF('Data Sheet'!B30>0, 'Data Sheet'!B31/'Data Sheet'!B30, 0) -> 0.41222581 | C18: =IF('Data Sheet'!C30>0, 'Data Sheet'!C31/'Data Sheet'!C30, 0) -> 0.50941772 | D18: =IF('Data Sheet'!D30>0, 'Data Sheet'!D31/'Data Sheet'!D30, 0) -> 0.4092833 | E18: =IF('Data Sheet'!E30>0, 'Data Sheet'!E31/'Data Sheet'!E30, 0) -> 0.46716019 | F18: =IF('Data Sheet'!F30>0, 'Data Sheet'!F31/'Data Sheet'!F30, 0) -> 0.42549636 | G18: =IF('Data Sheet'!G30>0, 'Data Sheet'!G31/'Data Sheet'!G30, 0) -> 0.54540039 | H18: =IF('Data Sheet'!H30>0, 'Data Sheet'!H31/'Data Sheet'!H30, 0) -> 0.6061137 | I18: =IF('Data Sheet'!I30>0, 'Data Sheet'!I31/'Data Sheet'!I30, 0) -> 0.59914281 | ... K18: =IF('Data Sheet'!K30>0, 'Data Sheet'!K31/'Data Sheet'!K30, 0) -> 0.64866943
A19: OPM | B19: =IF(B6>0,B6/B4,0) -> 0.19094292 | C19: =IF(C6>0,C6/C4,0) -> 0.19876258 | D19: =IF(D6>0,D6/D4,0) -> 0.19043659 | E19: =IF(E6>0,E6/E4,0) -> 0.19568163 | F19: =IF(F6>0,F6/F4,0) -> 0.2061916 | G19: =IF(G6>0,G6/G4,0) -> 0.22362856 | H19: =IF(H6>0,H6/H4,0) -> 0.16506525 | I19: =IF(I6>0,I6/I4,0) -> 0.18150467 | ... L19: =IF(L6>0,L6/L4,0) -> 0.18289012
G22: TRENDS: | H22: 10 YEARS | I22: 7 YEARS | J22: 5 YEARS | K22: 3 YEARS | L22: RECENT | M22: BEST | N22: WORST
G23: Sales Growth | H23: =IF(B4=0,"",POWER($K4/B4,1/9)-1) -> 0.10092015 | I23: =IF(D4=0,"",POWER($K4/D4,1/7)-1) -> 0.10528802 | J23: =IF(F4=0,"",POWER($K4/F4,1/5)-1) -> 0.10901062 | K23: =IF(H4=0,"",POWER($K4/H4, 1/3)-1) -> 0.052252258 | L23: =IF(ISERROR(MAX(IF(J4=0,"",(K4-J4)/J4),IF(K4=0,"",(L4-K4)/K4))),"",MAX(IF(J4=0,"",(K4-J4)/J4),IF(K4=0,"",(L4-K4)/K4))) -> 0.023303806 | M23: =MAX(K23:L23) -> 0.052252258 | N23: =MIN(H23:L23) -> 0.023303806
G24: OPM | H24: =IF(SUM(B4:$K$4)=0,"",SUMPRODUCT(B19:$K$19,B4:$K$4)/SUM(B4:$K$4)) -> 0.19293793 | I24: =IF(SUM(E4:$K$4)=0,"",SUMPRODUCT(E19:$K$19,E4:$K$4)/SUM(E4:$K$4)) -> 0.19284946 | J24: =IF(SUM(G4:$K$4)=0,"",SUMPRODUCT(G19:$K$19,G4:$K$4)/SUM(G4:$K$4)) -> 0.19075414 | K24: =IF(SUM(I4:$K$4)=0, "", SUMPRODUCT(I19:$K$19,I4:$K$4)/SUM(I4:$K$4)) -> 0.19107934 | L24: =L19 -> 0.18289012 | M24: =MAX(K24:L24) -> 0.19107934 | N24: =MIN(H24:L24) -> 0.18289012
G25: Price to Earning | H25: =IF(ISERROR(AVERAGEIF(B14:$L14,">0")),"",AVERAGEIF(B14:$L14,">0")) -> 62.484868 | I25: =IF(ISERROR(AVERAGEIF(E14:$L14,">0")),"",AVERAGEIF(E14:$L14,">0")) -> 66.725238 | J25: =IF(ISERROR(AVERAGEIF(G14:$L14,">0")),"",AVERAGEIF(G14:$L14,">0")) -> 68.049785 | K25: =IF(ISERROR(AVERAGEIF(I14:$L14,">0")),"",AVERAGEIF(I14:$L14,">0")) -> 58.321587 | L25: =L14 -> 57.547764 | M25: =MAX(K25:L25) -> 58.321587 | N25: =MIN(H25:L25) -> 57.547764

Sheet Quarters
A1: ='Profit & Loss'!A1 -> ASIAN PAINTS LTD | E1: =UPDATE | J1: SCREENER.IN
A3: Narration | B3: ='Data Sheet'!B41 -> 45199 | C3: ='Data Sheet'!C41 -> 45291 | D3: ='Data Sheet'!D41 -> 45382 | E3: ='Data Sheet'!E41 -> 45473 | F3: ='Data Sheet'!F41 -> 45565 | G3: ='Data Sheet'!G41 -> 45657 | H3: ='Data Sheet'!H41 -> 45747 | I3: ='Data Sheet'!I41 -> 45838 | ... K3: ='Data Sheet'!K41 -> 46022
A4: Sales | B4: ='Data Sheet'!B42 -> 8478.57 | C4: ='Data Sheet'!C42 -> 9103.09 | D4: ='Data Sheet'!D42 -> 8730.76 | E4: ='Data Sheet'!E42 -> 8969.73 | F4: ='Data Sheet'!F42 -> 8027.54 | G4: ='Data Sheet'!G42 -> 8549.44 | H4: ='Data Sheet'!H42 -> 8358.91 | I4: ='Data Sheet'!I42 -> 8938.55 | ... K4: ='Data Sheet'!K42 -> 8867.02
A5: Expenses | B5: ='Data Sheet'!B43 -> 6762.34 | C5: ='Data Sheet'!C43 -> 7047 | D5: ='Data Sheet'!D43 -> 7039.39 | E5: ='Data Sheet'!E43 -> 7275.96 | F5: ='Data Sheet'!F43 -> 6788.03 | G5: ='Data Sheet'!G43 -> 6912.71 | H5: ='Data Sheet'!H43 -> 6922.71 | I5: ='Data Sheet'!I43 -> 7313.58 | ... K5: ='Data Sheet'!K43 -> 7086.06
A6: Operating Profit | B6: ='Data Sheet'!B50 -> 1716.23 | C6: ='Data Sheet'!C50 -> 2056.09 | D6: ='Data Sheet'!D50 -> 1691.37 | E6: ='Data Sheet'!E50 -> 1693.77 | F6: ='Data Sheet'!F50 -> 1239.51 | G6: ='Data Sheet'!G50 -> 1636.73 | H6: ='Data Sheet'!H50 -> 1436.2 | I6: ='Data Sheet'!I50 -> 1624.97 | ... K6: ='Data Sheet'!K50 -> 1780.96
A7: Other Income | B7: ='Data Sheet'!B44 -> 194.33 | C7: ='Data Sheet'!C44 -> 186.46 | D7: ='Data Sheet'!D44 -> 212.43 | E7: ='Data Sheet'!E44 -> 192.93 | F7: ='Data Sheet'!F44 -> 24.53 | G7: ='Data Sheet'!G44 -> 192.82 | H7: ='Data Sheet'!H44 -> -60.06 | I7: ='Data Sheet'!I44 -> 229.11 | ... K7: ='Data Sheet'!K44 -> 69.14
A8: Depreciation | B8: ='Data Sheet'!B45 -> 208.72 | C8: ='Data Sheet'!C45 -> 220.35 | D8: ='Data Sheet'!D45 -> 225.61 | E8: ='Data Sheet'!E45 -> 227.7 | F8: ='Data Sheet'!F45 -> 241.99 | G8: ='Data Sheet'!G45 -> 255.55 | H8: ='Data Sheet'!H45 -> 301.1 | I8: ='Data Sheet'!I45 -> 300.87 | ... K8: ='Data Sheet'!K45 -> 313.07
A9: Interest | B9: ='Data Sheet'!B46 -> 50.9 | C9: ='Data Sheet'!C46 -> 54.42 | D9: ='Data Sheet'!D46 -> 54.1 | E9: ='Data Sheet'!E46 -> 55.38 | F9: ='Data Sheet'!F46 -> 63.01 | G9: ='Data Sheet'!G46 -> 55.84 | H9: ='Data Sheet'!H46 -> 52.79 | I9: ='Data Sheet'!I46 -> 44.5 | ... K9: ='Data Sheet'!K46 -> 47.94
A10: Profit before tax | B10: ='Data Sheet'!B47 -> 1650.94 | C10: ='Data Sheet'!C47 -> 1967.78 | D10: ='Data Sheet'!D47 -> 1624.09 | E10: ='Data Sheet'!E47 -> 1603.62 | F10: ='Data Sheet'!F47 -> 959.04 | G10: ='Data Sheet'!G47 -> 1518.16 | H10: ='Data Sheet'!H47 -> 1022.25 | I10: ='Data Sheet'!I47 -> 1508.71 | ... K10: ='Data Sheet'!K47 -> 1489.09
A11: Tax | B11: ='Data Sheet'!B48 -> 418.55 | C11: ='Data Sheet'!C48 -> 492.62 | D11: ='Data Sheet'!D48 -> 348.79 | E11: ='Data Sheet'!E48 -> 416.83 | F11: ='Data Sheet'!F48 -> 265.38 | G11: ='Data Sheet'!G48 -> 389.73 | H11: ='Data Sheet'!H48 -> 321.42 | I11: ='Data Sheet'!I48 -> 391.66 | ... K11: ='Data Sheet'!K48 -> 415.17
A12: Net profit | B12: ='Data Sheet'!B49 -> 1205.42 | C12: ='Data Sheet'!C49 -> 1447.72 | D12: ='Data Sheet'!D49 -> 1256.72 | E12: ='Data Sheet'!E49 -> 1169.98 | F12: ='Data Sheet'!F49 -> 694.64 | G12: ='Data Sheet'!G49 -> 1110.48 | H12: ='Data Sheet'!H49 -> 692.13 | I12: ='Data Sheet'!I49 -> 1099.77 | ... K12: ='Data Sheet'!K49 -> 1059.87
A14: OPM | B14: =IF(B4>0,B6/B4,"") -> 0.20241975 | C14: =IF(C4>0,C6/C4,"") -> 0.22586726 | D14: =IF(D4>0,D6/D4,"") -> 0.1937254 | E14: =IF(E4>0,E6/E4,"") -> 0.18883177 | F14: =IF(F4>0,F6/F4,"") -> 0.1544072 | G14: =IF(G4>0,G6/G4,"") -> 0.19144295 | H14: =IF(H4>0,H6/H4,"") -> 0.17181666 | I14: =IF(I4>0,I6/I4,"") -> 0.18179347 | ... K14: =IF(K4>0,K6/K4,"") -> 0.20085215

Sheet Balance Sheet
A1: ='Profit & Loss'!A1 -> ASIAN PAINTS LTD | E1: =UPDATE | J1: SCREENER.IN
A3: Narration | B3: ='Data Sheet'!B56 -> 42460 | C3: ='Data Sheet'!C56 -> 42825 | D3: ='Data Sheet'!D56 -> 43190 | E3: ='Data Sheet'!E56 -> 43555 | F3: ='Data Sheet'!F56 -> 43921 | G3: ='Data Sheet'!G56 -> 44286 | H3: ='Data Sheet'!H56 -> 44651 | I3: ='Data Sheet'!I56 -> 45016 | ... K3: ='Data Sheet'!K56 -> 45747
A4: Equity Share Capital | B4: ='Data Sheet'!B57 -> 95.92 | C4: ='Data Sheet'!C57 -> 95.92 | D4: ='Data Sheet'!D57 -> 95.92 | E4: ='Data Sheet'!E57 -> 95.92 | F4: ='Data Sheet'!F57 -> 95.92 | G4: ='Data Sheet'!G57 -> 95.92 | H4: ='Data Sheet'!H57 -> 95.92 | I4: ='Data Sheet'!I57 -> 95.92 | ... K4: ='Data Sheet'!K57 -> 95.92
A5: Reserves | B5: ='Data Sheet'!B58 -> 6428.9 | C5: ='Data Sheet'!C58 -> 7507.97 | D5: ='Data Sheet'!D58 -> 8314.31 | E5: ='Data Sheet'!E58 -> 9374.63 | F5: ='Data Sheet'!F58 -> 10034.24 | G5: ='Data Sheet'!G58 -> 12710.37 | H5: ='Data Sheet'!H58 -> 13715.64 | I5: ='Data Sheet'!I58 -> 15896.31 | ... K5: ='Data Sheet'!K58 -> 19303.89
A6: Borrowings | B6: ='Data Sheet'!B59 -> 323.29 | C6: ='Data Sheet'!C59 -> 560.34 | D6: ='Data Sheet'!D59 -> 533.43 | E6: ='Data Sheet'!E59 -> 1319.6 | F6: ='Data Sheet'!F59 -> 1118.5 | G6: ='Data Sheet'!G59 -> 1093.12 | H6: ='Data Sheet'!H59 -> 1586.88 | I6: ='Data Sheet'!I59 -> 1932.62 | ... K6: ='Data Sheet'!K59 -> 2290.29
A7: Other Liabilities | B7: ='Data Sheet'!B60 -> 3710.92 | C7: ='Data Sheet'!C60 -> 4240.96 | D7: ='Data Sheet'!D60 -> 4819.82 | E7: ='Data Sheet'!E60 -> 5458.69 | F7: ='Data Sheet'!F60 -> 4889.31 | G7: ='Data Sheet'!G60 -> 6455.93 | H7: ='Data Sheet'!H60 -> 7559.99 | I7: ='Data Sheet'!I60 -> 7854.48 | ... K7: ='Data Sheet'!K60 -> 8665.15
A8: Total | B8: ='Data Sheet'!B61 -> 10559.03 | C8: ='Data Sheet'!C61 -> 12405.19 | D8: ='Data Sheet'!D61 -> 13763.48 | E8: ='Data Sheet'!E61 -> 16248.84 | F8: ='Data Sheet'!F61 -> 16137.97 | G8: ='Data Sheet'!G61 -> 20355.34 | H8: ='Data Sheet'!H61 -> 22958.43 | I8: ='Data Sheet'!I61 -> 25779.33 | ... K8: ='Data Sheet'!K61 -> 30355.25
A10: Net Block | B10: ='Data Sheet'!B62 -> 3416.35 | C10: ='Data Sheet'!C62 -> 3303.74 | D10: ='Data Sheet'!D62 -> 3732.24 | E10: ='Data Sheet'!E62 -> 6496.56 | F10: ='Data Sheet'!F62 -> 6272.31 | G10: ='Data Sheet'!G62 -> 5858.52 | H10: ='Data Sheet'!H62 -> 5519.06 | I10: ='Data Sheet'!I62 -> 5770.46 | ... K10: ='Data Sheet'!K62 -> 9220.1
A11: Capital Work in Progress | B11: ='Data Sheet'!B63 -> 106.59 | C11: ='Data Sheet'!C63 -> 257.54 | D11: ='Data Sheet'!D63 -> 1405.11 | E11: ='Data Sheet'!E63 -> 209.67 | F11: ='Data Sheet'!F63 -> 140.24 | G11: ='Data Sheet'!G63 -> 182.98 | H11: ='Data Sheet'!H63 -> 426.43 | I11: ='Data Sheet'!I63 -> 1019.59 | ... K11: ='Data Sheet'!K63 -> 1254.49
A12: Investments | B12: ='Data Sheet'!B64 -> 2712.13 | C12: ='Data Sheet'!C64 -> 2651.99 | D12: ='Data Sheet'!D64 -> 2140.7 | E12: ='Data Sheet'!E64 -> 2568.58 | F12: ='Data Sheet'!F64 -> 2018.85 | G12: ='Data Sheet'!G64 -> 4736.8 | H12: ='Data Sheet'!H64 -> 3247.53 | I12: ='Data Sheet'!I64 -> 4261.71 | ... K12: ='Data Sheet'!K64 -> 4724.75
A13: Other Assets | B13: ='Data Sheet'!B65 -> 4323.96 | C13: ='Data Sheet'!C65 -> 6191.92 | D13: ='Data Sheet'!D65 -> 6485.43 | E13: ='Data Sheet'!E65 -> 6974.03 | F13: ='Data Sheet'!F65 -> 7706.57 | G13: ='Data Sheet'!G65 -> 9577.04 | H13: ='Data Sheet'!H65 -> 13765.41 | I13: ='Data Sheet'!I65 -> 14727.57 | ... K13: ='Data Sheet'!K65 -> 15155.91
A14: Total | B14: ='Data Sheet'!B66 -> 10559.03 | C14: ='Data Sheet'!C66 -> 12405.19 | D14: ='Data Sheet'!D66 -> 13763.48 | E14: ='Data Sheet'!E66 -> 16248.84 | F14: ='Data Sheet'!F66 -> 16137.97 | G14: ='Data Sheet'!G66 -> 20355.34 | H14: ='Data Sheet'!H66 -> 22958.43 | I14: ='Data Sheet'!I66 -> 25779.33 | ... K14: ='Data Sheet'!K66 -> 30355.25
A16: Working Capital | B16: =B13-B7 -> 613.04 | C16: =C13-C7 -> 1950.96 | D16: =D13-D7 -> 1665.61 | E16: =E13-E7 -> 1515.34 | F16: =F13-F7 -> 2817.26 | G16: =G13-G7 -> 3121.11 | H16: =H13-H7 -> 6205.42 | I16: =I13-I7 -> 6873.09 | ... K16: =K13-K7 -> 6490.76
A17: Debtors | B17: ='Data Sheet'!B67 -> 1186.84 | C17: ='Data Sheet'!C67 -> 1446.6 | D17: ='Data Sheet'!D67 -> 1730.63 | E17: ='Data Sheet'!E67 -> 1907.33 | F17: ='Data Sheet'!F67 -> 1795.22 | G17: ='Data Sheet'!G67 -> 2602.17 | H17: ='Data Sheet'!H67 -> 3871.44 | I17: ='Data Sheet'!I67 -> 4636.94 | ... K17: ='Data Sheet'!K67 -> 4313.65
A18: Inventory | B18: ='Data Sheet'!B68 -> 1998.24 | C18: ='Data Sheet'!C68 -> 2626.94 | D18: ='Data Sheet'!D68 -> 2658.31 | E18: ='Data Sheet'!E68 -> 3149.86 | F18: ='Data Sheet'!F68 -> 3389.81 | G18: ='Data Sheet'!G68 -> 3798.6 | H18: ='Data Sheet'!H68 -> 6152.98 | I18: ='Data Sheet'!I68 -> 6210.64 | ... K18: ='Data Sheet'!K68 -> 6719.27
A20: Debtor Days | B20: =IF('Profit & Loss'!B4>0,'Balance Sheet'!B17/('Profit & Loss'!B4/365),0) -> 30.353985 | C20: =IF('Profit & Loss'!C4>0,'Balance Sheet'!C17/('Profit & Loss'!C4/365),0) -> 35.055726 | D20: =IF('Profit & Loss'!D4>0,'Balance Sheet'!D17/('Profit & Loss'!D4/365),0) -> 37.545132 | E20: =IF('Profit & Loss'!E4>0,'Balance Sheet'!E17/('Profit & Loss'!E4/365),0) -> 36.183511 | F20: =IF('Profit & Loss'!F4>0,'Balance Sheet'!F17/('Profit & Loss'!F4/365),0) -> 32.420325 | G20: =IF('Profit & Loss'!G4>0,'Balance Sheet'!G17/('Profit & Loss'!G4/365),0) -> 43.743436 | H20: =IF('Profit & Loss'!H4>0,'Balance Sheet'!H17/('Profit & Loss'!H4/365),0) -> 48.557163 | I20: =IF('Profit & Loss'!I4>0,'Balance Sheet'!I17/('Profit & Loss'!I4/365),0) -> 49.073711 | ... K20: =IF('Profit & Loss'!K4>0,'Balance Sheet'!K17/('Profit & Loss'!K4/365),0) -> 46.437206
A21: Inventory Turnover | B21: =IF('Balance Sheet'!B18>0,'Profit & Loss'!B4/'Balance Sheet'!B18,0) -> 7.14203 | C21: =IF('Balance Sheet'!C18>0,'Profit & Loss'!C4/'Balance Sheet'!C18,0) -> 5.7336635 | D21: =IF('Balance Sheet'!D18>0,'Profit & Loss'!D4/'Balance Sheet'!D18,0) -> 6.3290399 | E21: =IF('Balance Sheet'!E18>0,'Profit & Loss'!E4/'Balance Sheet'!E18,0) -> 6.1082493 | F21: =IF('Balance Sheet'!F18>0,'Profit & Loss'!F4/'Balance Sheet'!F18,0) -> 5.9623548 | G21: =IF('Balance Sheet'!G18>0,'Profit & Loss'!G4/'Balance Sheet'!G18,0) -> 5.715998 | H21: =IF('Balance Sheet'!H18>0,'Profit & Loss'!H4/'Balance Sheet'!H18,0) -> 4.7296237 | I21: =IF('Balance Sheet'!I18>0,'Profit & Loss'!I4/'Balance Sheet'!I18,0) -> 5.5531459 | ... K21: =IF('Balance Sheet'!K18>0,'Profit & Loss'!K4/'Balance Sheet'!K18,0) -> 5.0460273
A23: Return on Equity | B23: =IF(SUM('Balance Sheet'!B4:B5)>0,'Profit & Loss'!B12/SUM('Balance Sheet'!B4:B5),"") -> 0.26746485 | C23: =IF(SUM('Balance Sheet'!C4:C5)>0,'Profit & Loss'!C12/SUM('Balance Sheet'!C4:C5),"") -> 0.25505761 | D23: =IF(SUM('Balance Sheet'!D4:D5)>0,'Profit & Loss'!D12/SUM('Balance Sheet'!D4:D5),"") -> 0.24243451 | E23: =IF(SUM('Balance Sheet'!E4:E5)>0,'Profit & Loss'!E12/SUM('Balance Sheet'!E4:E5),"") -> 0.22764465 | F23: =IF(SUM('Balance Sheet'!F4:F5)>0,'Profit & Loss'!F12/SUM('Balance Sheet'!F4:F5),"") -> 0.26704119 | G23: =IF(SUM('Balance Sheet'!G4:G5)>0,'Profit & Loss'!G12/SUM('Balance Sheet'!G4:G5),"") -> 0.24513657 | H23: =IF(SUM('Balance Sheet'!H4:H5)>0,'Profit & Loss'!H12/SUM('Balance Sheet'!H4:H5),"") -> 0.21942272 | I23: =IF(SUM('Balance Sheet'!I4:I5)>0,'Profit & Loss'!I12/SUM('Balance Sheet'!I4:I5),"") -> 0.25677782 | ... K23: =IF(SUM('Balance Sheet'!K4:K5)>0,'Profit & Loss'!K12/SUM('Balance Sheet'!K4:K5),"") -> 0.18903433
A24: Return on Capital Emp | C24: =IF((B4+B5+B6+C4+C5+C6)>0,('Profit & Loss'!C10+'Profit & Loss'!C9)*2/(B4+B5+B6+C4+C5+C6),"") -> 0.39925421 | D24: =IF((C4+C5+C6+D4+D5+D6)>0,('Profit & Loss'!D10+'Profit & Loss'!D9)*2/(C4+C5+C6+D4+D5+D6),"") -> 0.37175245 | E24: =IF((D4+D5+D6+E4+E5+E6)>0,('Profit & Loss'!E10+'Profit & Loss'!E9)*2/(D4+D5+D6+E4+E5+E6),"") -> 0.34626562 | F24: =IF((E4+E5+E6+F4+F5+F6)>0,('Profit & Loss'!F10+'Profit & Loss'!F9)*2/(E4+E5+E6+F4+F5+F6),"") -> 0.33912811 | G24: =IF((F4+F5+F6+G4+G5+G6)>0,('Profit & Loss'!G10+'Profit & Loss'!G9)*2/(F4+F5+F6+G4+G5+G6),"") -> 0.34960774 | H24: =IF((G4+G5+G6+H4+H5+H6)>0,('Profit & Loss'!H10+'Profit & Loss'!H9)*2/(G4+G5+G6+H4+H5+H6),"") -> 0.29238528 | I24: =IF((H4+H5+H6+I4+I5+I6)>0,('Profit & Loss'!I10+'Profit & Loss'!I9)*2/(H4+H5+H6+I4+I5+I6),"") -> 0.35010229 | J24: =IF((I4+I5+I6+J4+J5+J6)>0,('Profit & Loss'!J10+'Profit & Loss'!J9)*2/(I4+I5+I6+J4+J5+J6),"") -> 0.38606781 | K24: =IF((J4+J5+J6+K4+K5+K6)>0,('Profit & Loss'!K10+'Profit & Loss'!K9)*2/(J4+J5+J6+K4+K5+K6),"") -> 0.24853087

Sheet Cash Flow
A1: ='Balance Sheet'!A1 -> ASIAN PAINTS LTD | E1: =UPDATE | J1: SCREENER.IN
A3: Narration | B3: ='Data Sheet'!B81 -> 42460 | C3: ='Data Sheet'!C81 -> 42825 | D3: ='Data Sheet'!D81 -> 43190 | E3: ='Data Sheet'!E81 -> 43555 | F3: ='Data Sheet'!F81 -> 43921 | G3: ='Data Sheet'!G81 -> 44286 | H3: ='Data Sheet'!H81 -> 44651 | I3: ='Data Sheet'!I81 -> 45016 | ... K3: ='Data Sheet'!K81 -> 45747
A4: Cash from Operating Activity | B4: ='Data Sheet'!B82 -> 2242.95 | C4: ='Data Sheet'!C82 -> 1527.33 | D4: ='Data Sheet'!D82 -> 2113.44 | E4: ='Data Sheet'!E82 -> 2469.54 | F4: ='Data Sheet'!F82 -> 2631.89 | G4: ='Data Sheet'!G82 -> 3683.35 | H4: ='Data Sheet'!H82 -> 986.49 | I4: ='Data Sheet'!I82 -> 4193.43 | ... K4: ='Data Sheet'!K82 -> 4423.96
A5: Cash from Investing Activity | B5: ='Data Sheet'!B83 -> -866.21 | C5: ='Data Sheet'!C83 -> -681.11 | D5: ='Data Sheet'!D83 -> -1556.14 | E5: ='Data Sheet'!E83 -> -917.79 | F5: ='Data Sheet'!F83 -> -517.91 | G5: ='Data Sheet'!G83 -> -540.54 | H5: ='Data Sheet'!H83 -> -316.75 | I5: ='Data Sheet'!I83 -> -1282.34 | ... K5: ='Data Sheet'!K83 -> -940.91
A6: Cash from Financing Activity | B6: ='Data Sheet'!B84 -> -848.98 | C6: ='Data Sheet'!C84 -> -756.43 | D6: ='Data Sheet'!D84 -> -1379.14 | E6: ='Data Sheet'!E84 -> -1117.46 | F6: ='Data Sheet'!F84 -> -2465.2 | G6: ='Data Sheet'!G84 -> -650.4 | H6: ='Data Sheet'!H84 -> -1807.61 | I6: ='Data Sheet'!I84 -> -2140.05 | ... K6: ='Data Sheet'!K84 -> -3752.58
A7: Net Cash Flow | B7: ='Data Sheet'!B85 -> 527.76 | C7: ='Data Sheet'!C85 -> 89.79 | D7: ='Data Sheet'!D85 -> -821.84 | E7: ='Data Sheet'!E85 -> 434.29 | F7: ='Data Sheet'!F85 -> -351.22 | G7: ='Data Sheet'!G85 -> 2492.41 | H7: ='Data Sheet'!H85 -> -1137.87 | I7: ='Data Sheet'!I85 -> 771.04 | ... K7: ='Data Sheet'!K85 -> -269.53

Sheet Customization
A1: How to use it?
A3: You can customize this workbook as you want.
B4: You can add custom formating, add conditional formating, add your own formulas… do ANYTHING.
B5: Please don't edit the "Data Sheet" only.
A7: After customization, you can upload this back on Screener.
B8: Upload on: | C8: https://www.screener.in/excel/
A10: Download your customized workbooks now onwards.
B11: Now whenever you will "Export to excel" from Screener, it will export your customized file.
A14: TESTING:
B15: This is a testing feature currently.
B16: You can report any formula errors on the worksheet at: support@screener.in

Sheet Data Sheet
A1: COMPANY NAME | B1: ASIAN PAINTS LTD | E1: =IF(B2<>B3, "A NEW VERSION OF THE WORKSHEET IS AVAILABLE", "")
A2: LATEST VERSION | B2: 2.1 | E2: PLEASE DO NOT MAKE ANY CHANGES TO THIS SHEET
A3: CURRENT VERSION | B3: 2.1
A5: META
A6: Number of shares | B6: =IF(B9>0, B9/B8, 0) -> 95.917763
A7: Face Value | B7: 1
A8: Current Price | B8: 2307.1
A9: Market Capitalization | B9: 221291.87
A15: PROFIT & LOSS
A16: Report Date | B16: 42460 | C16: 42825 | D16: 43190 | E16: 43555 | F16: 43921 | G16: 44286 | H16: 44651 | I16: 45016 | J16: 45382 | K16: 45747
A17: Sales | B17: 14271.49 | C17: 15061.99 | D17: 16824.55 | E17: 19240.13 | F17: 20211.25 | G17: 21712.79 | H17: 29101.28 | I17: 34488.59 | J17: 35494.73 | K17: 33905.62
A18: Raw Material Cost | B18: 6569.83 | C18: 7452.6 | D18: 8128.17 | E18: 9974.4 | F18: 9986.19 | G18: 10425.55 | H18: 17123.25 | I18: 18985.53 | J18: 17410.84 | K18: 17504.51
A19: Change in Inventory | B19: -199.33 | C19: 528.6 | D19: -142.13 | E19: 293.26 | F19: 239.15 | G19: 92.45 | H19: 1324.97 | I19: 309.73 | J19: -363.8 | K19: 205
A20: Power and Fuel | B20: 114.48 | C20: 106.02 | D20: 110.3 | E20: 119.63 | F20: 114.93 | G20: 86.05 | H20: 117.23 | I20: 138.29 | J20: 133.25 | K20: 148.58
A21: Other Mfr. Exp | B21: 1535.22 | C21: 1662.75 | D21: 1691.68 | E21: 1862.35 | F21: 1941.92 | G21: 2068.31 | H21: 2880.45 | I21: 2916.2 | J21: 2767.18 | K21: 2687.4
A22: Employee Cost | B22: 994.98 | C22: 1039.89 | D22: 1121.89 | E22: 1242.69 | F22: 1371.27 | G22: 1547.61 | H22: 1794.61 | I22: 2036.41 | J22: 2334.92 | K22: 2605.78
A23: Selling and admin | B23: 3912.3 | C23: 4364.04 | D23: 2254.92 | E23: 2366.87 | F23: 2623.15 | G23: 2245.69 | H23: 2941.98 | I23: 3500.84 | J23: 3811.86 | K23: 3874.94
A24: Other Expenses | B24: -1779.69 | C24: -2028.47 | D24: 171.45 | E24: 202.51 | F24: 245.55 | G24: 576.43 | H24: 765.12 | I24: 961.21 | J24: 1087.9 | K24: 1283.2
A25: Other Income | B25: 213.39 | C25: 337.9 | D25: 336.41 | E25: 273.77 | F25: 350.1 | G25: 331.65 | H25: 295.88 | I25: 431.46 | J25: 820.96 | K25: 350.22
A26: Depreciation | B26: 275.58 | C26: 334.79 | D26: 360.47 | E26: 622.14 | F26: 780.5 | G26: 791.27 | H26: 816.36 | I26: 858.02 | J26: 853 | K26: 1026.34
A27: Interest | B27: 49 | C27: 37.33 | D27: 41.47 | E27: 110.47 | F27: 107.95 | G27: 91.63 | H27: 95.41 | I27: 144.45 | J27: 205.17 | K27: 227.02
... A31: Dividend Amount | B31: 719.4 | C31: 987.98 | D31: 834.5 | E31: 1007.16 | F31: 1151.04 | G31: 1712.17 | H31: 1836.87 | I31: 2460.35 | J31: 3194.14 | K31: 2378.82
A40: Quarters
A41: Report Date | B41: 45199 | C41: 45291 | D41: 45382 | E41: 45473 | F41: 45565 | G41: 45657 | H41: 45747 | I41: 45838 | J41: 45930 | K41: 46022
A42: Sales | B42: 8478.57 | C42: 9103.09 | D42: 8730.76 | E42: 8969.73 | F42: 8027.54 | G42: 8549.44 | H42: 8358.91 | I42: 8938.55 | J42: 8531.27 | K42: 8867.02
A43: Expenses | B43: 6762.34 | C43: 7047 | D43: 7039.39 | E43: 7275.96 | F43: 6788.03 | G43: 6912.71 | H43: 6922.71 | I43: 7313.58 | J43: 7027.89 | K43: 7086.06
A44: Other Income | B44: 194.33 | C44: 186.46 | D44: 212.43 | E44: 192.93 | F44: 24.53 | G44: 192.82 | H44: -60.06 | I44: 229.11 | J44: 236.94 | K44: 69.14
A45: Depreciation | B45: 208.72 | C45: 220.35 | D45: 225.61 | E45: 227.7 | F45: 241.99 | G45: 255.55 | H45: 301.1 | I45: 300.87 | J45: 304.93 | K45: 313.07
A46: Interest | B46: 50.9 | C46: 54.42 | D46: 54.1 | E46: 55.38 | F46: 63.01 | G46: 55.84 | H46: 52.79 | I46: 44.5 | J46: 43.87 | K46: 47.94
A47: Profit before tax | B47: 1650.94 | C47: 1967.78 | D47: 1624.09 | E47: 1603.62 | F47: 959.04 | G47: 1518.16 | H47: 1022.25 | I47: 1508.71 | J47: 1391.52 | K47: 1489.09
A48: Tax | B48: 418.55 | C48: 492.62 | D48: 348.79 | E48: 416.83 | F48: 265.38 | G48: 389.73 | H48: 321.42 | I48: 391.66 | J48: 373.29 | K48: 415.17
A49: Net profit | B49: 1205.42 | C49: 1447.72 | D49: 1256.72 | E49: 1169.98 | F49: 694.64 | G49: 1110.48 | H49: 692.13 | I49: 1099.77 | J49: 993.59 | K49: 1059.87
A50: Operating Profit | B50: 1716.23 | C50: 2056.09 | D50: 1691.37 | E50: 1693.77 | F50: 1239.51 | G50: 1636.73 | H50: 1436.2 | I50: 1624.97 | J50: 1503.38 | K50: 1780.96
A55: BALANCE SHEET
A56: Report Date | B56: 42460 | C56: 42825 | D56: 43190 | E56: 43555 | F56: 43921 | G56: 44286 | H56: 44651 | I56: 45016 | J56: 45382 | K56: 45747
A57: Equity Share Capital | B57: 95.92 | C57: 95.92 | D57: 95.92 | E57: 95.92 | F57: 95.92 | G57: 95.92 | H57: 95.92 | I57: 95.92 | J57: 95.92 | K57: 95.92
A58: Reserves | B58: 6428.9 | C58: 7507.97 | D58: 8314.31 | E58: 9374.63 | F58: 10034.24 | G58: 12710.37 | H58: 13715.64 | I58: 15896.31 | J58: 18632.38 | K58: 19303.89
A59: Borrowings | B59: 323.29 | C59: 560.34 | D59: 533.43 | E59: 1319.6 | F59: 1118.5 | G59: 1093.12 | H59: 1586.88 | I59: 1932.62 | J59: 2474.38 | K59: 2290.29
A60: Other Liabilities | B60: 3710.92 | C60: 4240.96 | D60: 4819.82 | E60: 5458.69 | F60: 4889.31 | G60: 6455.93 | H60: 7559.99 | I60: 7854.48 | J60: 8698.09 | K60: 8665.15
A61: Total | B61: 10559.03 | C61: 12405.19 | D61: 13763.48 | E61: 16248.84 | F61: 16137.97 | G61: 20355.34 | H61: 22958.43 | I61: 25779.33 | J61: 29900.77 | K61: 30355.25
...

Sheet Assumption_A.p.
C3: 44651 | D3: 45016 | E3: 45382 | F3: 45747 | K3: 44651 | L3: 45016 | M3: 45382 | N3: 45747 | O3: CAGR
Q4: sales | R4: 0.06
B5: Sales | C5: 29101.28 | D5: 34488.59 | E5: 35494.73 | F5: 33905.62 | J5: Sales | L5: =D5/C5-1 -> 0.18512278 | M5: =E5/D5-1 -> 0.029173127 | N5: =F5/E5-1 -> -0.044770308 | O5: =AVERAGE(K5:N5) -> 0.056508534 | Q5: Expenses % sales | R5: 0.82
B6: Expenses | C6: 24297.67 | D6: 28228.75 | E6: 27909.75 | F6: 27899.41 | J6: Expenses | K6: =C6/C5 -> 0.83493475 | L6: =D6/D5 -> 0.81849533 | M6: =E6/E5 -> 0.78630687 | N6: =F6/F5 -> 0.82285503 | O6: =AVERAGE(K6:N6) -> 0.815648 | Q6: Depreciation | R6: 0.03
B7: Operating Profit | C7: 4803.61 | D7: 6259.84 | E7: 7584.98 | F7: 6006.21 | J7: Operating Profit | Q7: Tax | R7: 0.26
B8: Other Income | C8: 295.88 | D8: 431.46 | E8: 820.96 | F8: 350.22 | J8: Other Income
B9: Depreciation | C9: 816.36 | D9: 858.02 | E9: 853 | F9: 1026.34 | J9: Depreciation | K9: =C9/C5 -> 0.028052374 | L9: =D9/D5 -> 0.024878373 | M9: =E9/E5 -> 0.024031737 | N9: =F9/F5 -> 0.030270498 | O9: =AVERAGE(K9:N9) -> 0.026808245 | Q9: Borrowing | R9: 0.14
B10: Interest | C10: 95.41 | D10: 144.45 | E10: 205.17 | F10: 227.02 | J10: Interest | Q10: Others Liabilities | R10: 0.25
B11: Profit before tax | C11: 4187.72 | D11: 5688.83 | E11: 7347.77 | F11: 5103.07 | J11: Profit before tax | Q11: Share Capital | R11: 96
B12: Tax | C12: 1102.91 | D12: 1493.5 | E12: 1790.08 | F12: 1393.36 | J12: Tax | K12: =C12/C11 -> 0.26336766 | L12: =D12/D11 -> 0.26253201 | M12: =E12/E11 -> 0.24362221 | N12: =F12/F11 -> 0.27304348 | O12: =AVERAGE(K12:N12) -> 0.26064134
B13: Net profit | C13: 3030.57 | D13: 4106.45 | E13: 5460.23 | F13: 3667.23 | J13: Net profit
Q15: CWIP | R15: 0.83
Q16: Investments | R16: 1.14
C17: 44651 | D17: 45016 | E17: 45382 | F17: 45747 | K17: 44651 | L17: 45016 | M17: 45382 | N17: 45747 | Q17: Others Assets | R17: 0.42
B19: Equity Share Capital | C19: 95.92 | D19: 95.92 | E19: 95.92 | F19: 95.92 | J19: Equity Share Capital | K19: =C19 -> 95.92 | L19: =D19 -> 95.92 | M19: =E19 -> 95.92 | N19: =F19 -> 95.92 | O19: =N19 -> 95.92
B20: Reserves | C20: 13715.64 | D20: 15896.31 | E20: 18632.38 | F20: 19303.89 | J20: Reserves
B21: Borrowings | C21: 1586.88 | D21: 1932.62 | E21: 2474.38 | F21: 2290.29 | J21: Borrowings | L21: =D21/C21-1 -> 0.21787407 | M21: =E21/D21-1 -> 0.28032412 | N21: =F21/E21-1 -> -0.074398435 | O21: =AVERAGE(K21:N21) -> 0.14126658
B22: Other Liabilities | C22: 7559.99 | D22: 7854.48 | E22: 8698.09 | F22: 8665.15 | J22: Other Liabilities | K22: =C22/C5 -> 0.25978204 | L22: =D22/D5 -> 0.22774141 | M22: =E22/E5 -> 0.245053 | N22: =F22/F5 -> 0.25556678 | O22: =AVERAGE(K22:N22) -> 0.24703581
B23: Total | C23: =SUM(C19:C22) -> 22958.43 | D23: =SUM(D19:D22) -> 25779.33 | E23: =SUM(E19:E22) -> 29900.77 | F23: =SUM(F19:F22) -> 30355.25 | J23: Total
B26: Cash | C26: 864.33 | D26: 843.82 | E26: 1084.01 | F26: 781.98 | J26: Cash
B27: Net Block | C27: 5519.06 | D27: 5770.46 | E27: 7146.62 | F27: 9220.1 | J27: Net Block
B28: Capital Work in Progress | C28: 426.43 | D28: 1019.59 | E28: 2698.37 | F28: 1254.49 | J28: Capital Work in Progress | L28: =D28/C28-1 -> 1.3909903 | M28: =E28/D28-1 -> 1.6465246 | N28: =F28/E28-1 -> -0.53509341 | O28: =AVERAGE(K28:N28) -> 0.8341405
B29: Investments | C29: 3247.53 | D29: 4261.71 | E29: 4587.92 | F29: 4724.75 | J29: Investments | L29: =D29/C29 -> 1.3122927 | M29: =E29/D29 -> 1.0765444 | N29: =F29/E29 -> 1.029824 | O29: =AVERAGE(K29:N29) -> 1.1395537
B30: Other Assets | C30: 12901.08 | D30: 13883.75 | E30: 14383.85 | F30: 14373.93 | J30: Other Assets | K30: =C30/C5 -> 0.44331658 | L30: =D30/D5 -> 0.40256067 | M30: =E30/E5 -> 0.40523903 | N30: =F30/F5 -> 0.42393945 | O30: =AVERAGE(K30:N30) -> 0.41876393
B31: Total | C31: =SUM(C26:C30) -> 22958.43 | D31: =SUM(D26:D30) -> 25779.33 | E31: =SUM(E26:E30) -> 29900.77 | F31: =SUM(F26:F30) -> 30355.25 | J31: Total
B34: Balance Check | C34: =C23-C31 -> 0 | D34: =D23-D31 -> 0 | E34: =E23-E31 -> 0 | F34: =F23-F31 -> 0 | J34: Capex
J35: End Net Block | K35: =C27 -> 5519.06 | L35: =D27 -> 5770.46 | M35: =E27 -> 7146.62 | N35: =F27 -> 9220.1
J36: Beginning Net Block | L36: =-K35 -> -5519.06 | M36: =-L35 -> -5770.46 | N36: =-M35 -> -7146.62
J37: Depreciation | L37: =D9 -> 858.02 | M37: =E9 -> 853 | N37: =F9 -> 1026.34
J38: Capex | L38: =SUM(L35:L37) -> 1109.42 | M38: =SUM(M35:M37) -> 2229.16 | N38: =SUM(N35:N37) -> 3099.82
J40: % of sales | L40: =L38/D5 -> 0.03216774 | M40: =M38/E5 -> 0.062802563 | N40: =N38/F5 -> 0.091424961 | O40: =AVERAGE(L40:N40) -> 0.062131755
B41: Cash & Bank | C41: 864.33 | D41: 843.82 | E41: 1084.01 | F41: 781.98
B42: Total Others Assets | C42: 13765.41 | D42: 14727.57 | E42: 15467.86 | F42: 15155.91
B43: Other Assets | C43: =C42-C41 -> 12901.08 | D43: =D42-D41 -> 13883.75 | E43: =E42-E41 -> 14383.85 | F43: =F42-F41 -> 14373.93

Sheet Three_ Statement_Models (2)
C3: 45747 | D3: 46112 | E3: 46477 | F3: 46843 | G3: 47208 | M3: sales | N3: 0.06
M4: Expenses % sales | N4: 0.82
B5: Sales | C5: 33905.62 | D5: =C5*1.06 -> 35939.957 | E5: =D5*1.06 -> 38096.355 | F5: =E5*1.06 -> 40382.136 | G5: =F5*1.06 -> 42805.064 | M5: Depreciation | N5: 0.03
B6: Expenses | C6: 27899.41 | D6: =-D5*0.82 -> -29470.765 | E6: =-E5*0.82 -> -31239.011 | F6: =-F5*0.82 -> -33113.351 | G6: =-G5*0.82 -> -35100.153 | M6: Tax | N6: 0.26
B7: Operating Profit | C7: 6006.21 | D7: =SUM(D5:D6) -> 6469.1923 | E7: =SUM(E5:E6) -> 6857.3438 | F7: =SUM(F5:F6) -> 7268.7845 | G7: =SUM(G5:G6) -> 7704.9115
B8: Other Income | C8: 350.22 | M8: Borrowing | N8: 0.14
B9: Depreciation | C9: 1026.34 | D9: =-D5*0.03 -> -1078.1987 | E9: =-E5*0.03 -> -1142.8906 | F9: =-F5*0.03 -> -1211.4641 | G9: =-G5*0.03 -> -1284.1519 | M9: Others Liabilities | N9: 0.25
B10: Interest | C10: 227.02 | M10: Share Capital | N10: 96
B11: Profit before tax | C11: 5103.07 | D11: =SUM(D7:D10) -> 5390.9936 | E11: =SUM(E7:E10) -> 5714.4532 | F11: =SUM(F7:F10) -> 6057.3204 | G11: =SUM(G7:G10) -> 6420.7596 | M11: Dividend
B12: Tax | C12: 1393.36 | D12: =-D11*0.26 -> -1401.6583 | E12: =-E11*0.26 -> -1485.7578 | F12: =-F11*0.26 -> -1574.9033 | G12: =-G11*0.26 -> -1669.3975
B13: Net profit | C13: 3667.23 | D13: =SUM(D11:D12) -> 3989.3352 | E13: =SUM(E11:E12) -> 4228.6954 | F13: =SUM(F11:F12) -> 4482.4171 | G13: =SUM(G11:G12) -> 4751.3621 | M13: CWIP | N13: 0.83
M14: Investments | N14: 1.14
M15: Others Assets | N15: 0.42
M18: Reserve | N18: 45747 | O18: 46112 | P18: 46477 | Q18: 46843 | R18: 47208
M19: Beginning Reserve | O19: =N22 -> 19304 | P19: =O22 -> 21298.668 | Q19: =P22 -> 23413.015 | R19: =Q22 -> 25654.224
C20: 45747 | D20: 46112 | E20: 46477 | F20: 46843 | G20: 47208 | M20: Net Income | O20: =D13 -> 3989.3352 | P20: =E13 -> 4228.6954 | Q20: =F13 -> 4482.4171 | R20: =G13 -> 4751.3621
M21: Dividend | O21: =-O20*0.5 -> -1994.6676 | P21: =-P20*0.5 -> -2114.3477 | Q21: =-Q20*0.5 -> -2241.2085 | R21: =-R20*0.5 -> -2375.6811
B22: Equity Share Capital | C22: 95.92 | D22: =C22 -> 95.92 | E22: =D22 -> 95.92 | F22: =E22 -> 95.92 | G22: =F22 -> 95.92 | M22: End Reserve | N22: 19304 | O22: =SUM(O19:O21) -> 21298.668 | P22: =SUM(P19:P21) -> 23413.015 | Q22: =SUM(Q19:Q21) -> 25654.224 | R22: =SUM(R19:R21) -> 28029.905
B23: Revolver
B24: Reserves | C24: 19303.89 | D24: =O22 -> 21298.668 | E24: =P22 -> 23413.015 | F24: =Q22 -> 25654.224 | G24: =R22 -> 28029.905
B25: Borrowings | C25: 2290.29 | D25: =C25*1.14 -> 2610.9306 | E25: =D25*1.14 -> 2976.4609 | F25: =E25*1.14 -> 3393.1654 | G25: =F25*1.14 -> 3868.2086
B26: Other Liabilities | C26: 8665.15 | D26: =D5*0.25 -> 8984.9893 | E26: =E5*0.25 -> 9524.0887 | F26: =F5*0.25 -> 10095.534 | G26: =G5*0.25 -> 10701.266 | M26: Net Block | N26: 45747 | O26: 46112 | P26: 46477 | Q26: 46843 | R26: 47208
B27: Total | C27: =SUM(C22:C26) -> 30355.25 | D27: =SUM(D22:D26) -> 32990.508 | E27: =SUM(E22:E26) -> 36009.485 | F27: =SUM(F22:F26) -> 39238.843 | G27: =SUM(G22:G26) -> 42695.299 | M27: Beginning Net Block | O27: =N30 -> 9220 | P27: =O30 -> 10298.199 | Q27: =P30 -> 11441.089 | R27: =Q30 -> 12652.553
M28: Capex | O28: =D5*0.06 -> 2156.3974 | P28: =E5*0.06 -> 2285.7813 | Q28: =F5*0.06 -> 2422.9282 | R28: =G5*0.06 -> 2568.3038
M29: Depreciation | O29: =D9 -> -1078.1987 | P29: =E9 -> -1142.8906 | Q29: =F9 -> -1211.4641 | R29: =G9 -> -1284.1519
B30: Cash | C30: 781.98 | M30: End Net Block | N30: 9220 | O30: =SUM(O27:O29) -> 10298.199 | P30: =SUM(P27:P29) -> 11441.089 | Q30: =SUM(Q27:Q29) -> 12652.553 | R30: =SUM(R27:R29) -> 13936.705
B31: Net Block | C31: 9220.1 | D31: =O30 -> 10298.199 | E31: =P30 -> 11441.089 | F31: =Q30 -> 12652.553 | G31: =R30 -> 13936.705
B32: Capital Work in Progress | C32: 1254.49 | D32: =C32*1.83 -> 2295.7167 | E32: =D32*1.83 -> 4201.1616 | F32: =E32*1.83 -> 7688.1257 | G32: =F32*1.83 -> 14069.27
B33: Investments | C33: 4724.75 | D33: =C33*2.14 -> 10110.965 | E33: =D33*2.14 -> 21637.465 | F33: =E33*2.14 -> 46304.175 | G33: =F33*2.14 -> 99090.935
B34: Other Assets | C34: 14373.93 | D34: =D5*0.42 -> 15094.782 | E34: =E5*0.42 -> 16000.469 | F34: =F5*0.42 -> 16960.497 | G34: =G5*0.42 -> 17978.127 | O34: =SUM(O28:O29) -> 1078.1987 | P34: =SUM(P28:P29) -> 1142.8906 | Q34: =SUM(Q28:Q29) -> 1211.4641 | R34: =SUM(R28:R29) -> 1284.1519
B35: Total | C35: =SUM(C30:C34) -> 30355.25 | D35: =SUM(D30:D34) -> 37799.662 | E35: =SUM(E30:E34) -> 53280.185 | F35: =SUM(F30:F34) -> 83605.351 | G35: =SUM(G30:G34) -> 145075.04
B38: Balance Check | C38: =C27-C35 -> 0 | D38: =D27-D35 -> -4809.1549 | E38: =E27-E35 -> -17270.7 | F38: =F27-F35 -> -44366.508 | G38: =G27-G35 -> -102379.74
J41: Deprecation is added to in op , it is main purposes to reduce capex due to in balance sheet change in dep is not considered
C42: 45747 | D42: 46112 | E42: 46477 | F42: 46843 | G42: 47208
B44: Cash Flow Statement
B45: Net INCOME | D45: =D13 -> 3989.3352 | E45: =E13 -> 4228.6954 | F45: =F13 -> 4482.4171 | G45: =G13 -> 4751.3621
B46: Depreciation | J46: =-D9 -> 1078.1987 | K46: =-E9 -> 1142.8906 | L46: =-F9 -> 1211.4641 | M46: =-G9 -> 1284.1519
B47: Other Assets | D47: =C34-D34 -> -720.85202 | E47: =D34-E34 -> -905.68692 | F47: =E34-F34 -> -960.02814 | G47: =F34-G34 -> -1017.6298
B48: Others Liabilities | D48: =D26-C26 -> 319.8393 | E48: =E26-D26 -> 539.09936 | F48: =F26-E26 -> 571.44532 | G48: =G26-F26 -> 605.73204
B49: Change in Op | D49: =SUM(D45:D48) -> 3588.3225 | E49: =SUM(E45:E48) -> 3862.1078 | F49: =SUM(F45:F48) -> 4093.8343 | G49: =SUM(G45:G48) -> 4339.4643
...

Sheet Three_ Statement_Models
C3: 45747 | D3: 46112 | E3: 46477 | F3: 46843 | G3: 47208 | M3: sales | N3: 0.06
M4: Expenses % sales | N4: 0.82
B5: Sales | C5: 33905.62 | D5: =C5*1.06 -> 35939.957 | E5: =D5*1.06 -> 38096.355 | F5: =E5*1.06 -> 40382.136 | G5: =F5*1.06 -> 42805.064 | M5: Depreciation | N5: 0.03
B6: Expenses | C6: 27899.41 | D6: =-D5*0.82 -> -29470.765 | E6: =-E5*0.82 -> -31239.011 | F6: =-F5*0.82 -> -33113.351 | G6: =-G5*0.82 -> -35100.153 | M6: Tax | N6: 0.26
B7: Operating Profit | C7: 6006.21 | D7: =SUM(D5:D6) -> 6469.1923 | E7: =SUM(E5:E6) -> 6857.3438 | F7: =SUM(F5:F6) -> 7268.7845 | G7: =SUM(G5:G6) -> 7704.9115
B8: Other Income | C8: 350.22 | M8: Borrowing | N8: 0.14
B9: Depreciation | C9: 1026.34 | D9: =-D5*0.03 -> -1078.1987 | E9: =-E5*0.03 -> -1142.8906 | F9: =-F5*0.03 -> -1211.4641 | G9: =-G5*0.03 -> -1284.1519 | M9: Others Liabilities | N9: 0.25
B10: Interest | C10: 227.02 | M10: Share Capital | N10: 96
B11: Profit before tax | C11: 5103.07 | D11: =SUM(D7:D10) -> 5390.9936 | E11: =SUM(E7:E10) -> 5714.4532 | F11: =SUM(F7:F10) -> 6057.3204 | G11: =SUM(G7:G10) -> 6420.7596 | M11: Dividend
B12: Tax | C12: 1393.36 | D12: =-D11*0.26 -> -1401.6583 | E12: =-E11*0.26 -> -1485.7578 | F12: =-F11*0.26 -> -1574.9033 | G12: =-G11*0.26 -> -1669.3975
B13: Net profit | C13: 3667.23 | D13: =SUM(D11:D12) -> 3989.3352 | E13: =SUM(E11:E12) -> 4228.6954 | F13: =SUM(F11:F12) -> 4482.4171 | G13: =SUM(G11:G12) -> 4751.3621 | M13: CWIP | N13: 0.83
M14: Investments | N14: 1.14
M15: Others Assets | N15: 0.42
M18: Reserve | N18: 45747 | O18: 46112 | P18: 46477 | Q18: 46843 | R18: 47208
M19: Beginning Reserve | O19: =N22 -> 19304 | P19: =O22 -> 21298.668 | Q19: =P22 -> 23413.015 | R19: =Q22 -> 25654.224
C20: 45747 | D20: 46112 | E20: 46477 | F20: 46843 | G20: 47208 | M20: Net Income | O20: =D13 -> 3989.3352 | P20: =E13 -> 4228.6954 | Q20: =F13 -> 4482.4171 | R20: =G13 -> 4751.3621
M21: Dividend | O21: =-O20*0.5 -> -1994.6676 | P21: =-P20*0.5 -> -2114.3477 | Q21: =-Q20*0.5 -> -2241.2085 | R21: =-R20*0.5 -> -2375.6811
B22: Equity Share Capital | C22: 95.92 | D22: =C22 -> 95.92 | E22: =D22 -> 95.92 | F22: =E22 -> 95.92 | G22: =F22 -> 95.92 | M22: End Reserve | N22: 19304 | O22: =SUM(O19:O21) -> 21298.668 | P22: =SUM(P19:P21) -> 23413.015 | Q22: =SUM(Q19:Q21) -> 25654.224 | R22: =SUM(R19:R21) -> 28029.905
B23: Revolver
B24: Reserves | C24: 19303.89 | D24: =O22 -> 21298.668 | E24: =P22 -> 23413.015 | F24: =Q22 -> 25654.224 | G24: =R22 -> 28029.905
B25: Borrowings | C25: 2290.29 | D25: =C25*1.14 -> 2610.9306 | E25: =D25*1.14 -> 2976.4609 | F25: =E25*1.14 -> 3393.1654 | G25: =F25*1.14 -> 3868.2086
B26: Other Liabilities | C26: 8665.15 | D26: =D5*0.25 -> 8984.9893 | E26: =E5*0.25 -> 9524.0887 | F26: =F5*0.25 -> 10095.534 | G26: =G5*0.25 -> 10701.266 | M26: Net Block | N26: 45747 | O26: 46112 | P26: 46477 | Q26: 46843 | R26: 47208
B27: Total | C27: =SUM(C22:C26) -> 30355.25 | D27: =SUM(D22:D26) -> 32990.508 | E27: =SUM(E22:E26) -> 36009.485 | F27: =SUM(F22:F26) -> 39238.843 | G27: =SUM(G22:G26) -> 42695.299 | M27: Beginning Net Block | O27: =N30 -> 9220 | P27: =O30 -> 10298.199 | Q27: =P30 -> 11441.089 | R27: =Q30 -> 12652.553
M28: Capex | O28: =D5*0.06 -> 2156.3974 | P28: =E5*0.06 -> 2285.7813 | Q28: =F5*0.06 -> 2422.9282 | R28: =G5*0.06 -> 2568.3038
M29: Depreciation | O29: =D9 -> -1078.1987 | P29: =E9 -> -1142.8906 | Q29: =F9 -> -1211.4641 | R29: =G9 -> -1284.1519
B30: Cash | C30: 781.98 | M30: End Net Block | N30: 9220 | O30: =SUM(O27:O29) -> 10298.199 | P30: =SUM(P27:P29) -> 11441.089 | Q30: =SUM(Q27:Q29) -> 12652.553 | R30: =SUM(R27:R29) -> 13936.705
B31: Net Block | C31: 9220.1 | D31: =O30 -> 10298.199 | E31: =P30 -> 11441.089 | F31: =Q30 -> 12652.553 | G31: =R30 -> 13936.705
B32: Capital Work in Progress | C32: 1254.49 | D32: =C32*1.83 -> 2295.7167 | E32: =D32*1.83 -> 4201.1616 | F32: =E32*1.83 -> 7688.1257 | G32: =F32*1.83 -> 14069.27
B33: Investments | C33: 4724.75 | D33: =C33*2.14 -> 10110.965 | E33: =D33*2.14 -> 21637.465 | F33: =E33*2.14 -> 46304.175 | G33: =F33*2.14 -> 99090.935
B34: Other Assets | C34: 14373.93 | D34: =D5*0.42 -> 15094.782 | E34: =E5*0.42 -> 16000.469 | F34: =F5*0.42 -> 16960.497 | G34: =G5*0.42 -> 17978.127 | O34: =SUM(O28:O29) -> 1078.1987 | P34: =SUM(P28:P29) -> 1142.8906 | Q34: =SUM(Q28:Q29) -> 1211.4641 | R34: =SUM(R28:R29) -> 1284.1519
B35: Total | C35: =SUM(C30:C34) -> 30355.25 | D35: =SUM(D30:D34) -> 37799.662 | E35: =SUM(E30:E34) -> 53280.185 | F35: =SUM(F30:F34) -> 83605.351 | G35: =SUM(G30:G34) -> 145075.04
B38: Balance Check | C38: =C27-C35 -> 0 | D38: =D27-D35 -> -4809.1549 | E38: =E27-E35 -> -17270.7 | F38: =F27-F35 -> -44366.508 | G38: =G27-G35 -> -102379.74
J41: Deprecation is added to in op , it is main purposes to reduce capex due to in balance sheet change in dep is not considered
C42: 45747 | D42: 46112 | E42: 46477 | F42: 46843 | G42: 47208
B44: Cash Flow Statement
B45: Net INCOME | D45: =D13 -> 3989.3352 | E45: =E13 -> 4228.6954 | F45: =F13 -> 4482.4171 | G45: =G13 -> 4751.3621
B46: Depreciation | J46: =-D9 -> 1078.1987 | K46: =-E9 -> 1142.8906 | L46: =-F9 -> 1211.4641 | M46: =-G9 -> 1284.1519
B47: Other Assets | D47: =C34-D34 -> -720.85202 | E47: =D34-E34 -> -905.68692 | F47: =E34-F34 -> -960.02814 | G47: =F34-G34 -> -1017.6298
B48: Others Liabilities | D48: =D26-C26 -> 319.8393 | E48: =E26-D26 -> 539.09936 | F48: =F26-E26 -> 571.44532 | G48: =G26-F26 -> 605.73204
B49: Change in Op | D49: =SUM(D45:D48) -> 3588.3225 | E49: =SUM(E45:E48) -> 3862.1078 | F49: =SUM(F45:F48) -> 4093.8343 | G49: =SUM(G45:G48) -> 4339.4643
...
